Microsoft Windows [Version 10.0.19045.5737]
(c) Microsoft Corporation. All rights reserved.

C:\Users\Msys\Desktop\Axsos_Assignments\python_stack\my_environments>call py3Env\Scripts\activate

(py3Env) C:\Users\Msys\Desktop\Axsos_Assignments\python_stack\my_environments>cd ..

(py3Env) C:\Users\Msys\Desktop\Axsos_Assignments\python_stack>dir
 Volume in drive C has no label.
 Volume Serial Number is BCE9-A292

 Directory of C:\Users\Msys\Desktop\Axsos_Assignments\python_stack

03/23/2025  12:58 PM    <DIR>          .
03/23/2025  12:58 PM    <DIR>          ..
03/23/2025  12:07 AM    <DIR>          django
04/07/2025  12:13 AM    <DIR>          my_environments
04/13/2025  01:31 PM    <DIR>          Python assignments and projects
03/23/2025  12:05 AM    <DIR>          _python
               0 File(s)              0 bytes
               6 Dir(s)  270,222,540,800 bytes free

(py3Env) C:\Users\Msys\Desktop\Axsos_Assignments\python_stack>cd django

(py3Env) C:\Users\Msys\Desktop\Axsos_Assignments\python_stack\django>cd django_orm

(py3Env) C:\Users\Msys\Desktop\Axsos_Assignments\python_stack\django\django_orm>django-admin startproject single_model_orm

(py3Env) C:\Users\Msys\Desktop\Axsos_Assignments\python_stack\django\django_orm>cd single_model_orm

(py3Env) C:\Users\Msys\Desktop\Axsos_Assignments\python_stack\django\django_orm\single_model_orm>python manage.py

Type 'manage.py help <subcommand>' for help on a specific subcommand.

Available subcommands:

[auth]
    changepassword
    createsuperuser

[contenttypes]
    remove_stale_contenttypes

[django]
    check
    compilemessages
    createcachetable
    dbshell
    diffsettings
    dumpdata
    flush
    inspectdb
    loaddata
    makemessages
    makemigrations
    migrate
    sendtestemail
    shell
    showmigrations
    sqlflush
    sqlmigrate
    sqlsequencereset
    squashmigrations
    startapp
    startproject
    test
    testserver

[sessions]
    clearsessions

[staticfiles]
    collectstatic
    findstatic
    runserver

(py3Env) C:\Users\Msys\Desktop\Axsos_Assignments\python_stack\django\django_orm\single_model_orm>python manage.py startapp users_app

(py3Env) C:\Users\Msys\Desktop\Axsos_Assignments\python_stack\django\django_orm\single_model_orm>code .

(py3Env) C:\Users\Msys\Desktop\Axsos_Assignments\python_stack\django\django_orm\single_model_orm>python manage.py runserver
Watching for file changes with StatReloader
Performing system checks...

System check identified no issues (0 silenced).

You have 17 unapplied migration(s). Your project may not work properly until you apply the migrations for app(s): admin, auth, contenttypes, sessions.
Run 'python manage.py migrate' to apply them.
April 14, 2025 - 13:16:45
Django version 2.2.4, using settings 'single_model_orm.settings'
Starting development server at http://127.0.0.1:8000/
Quit the server with CTRL-BREAK.
[14/Apr/2025 13:17:11] "GET / HTTP/1.1" 200 16348
[14/Apr/2025 13:17:11] "GET /static/admin/css/fonts.css HTTP/1.1" 304 0
[14/Apr/2025 13:17:11] "GET /static/admin/fonts/Roboto-Bold-webfont.woff HTTP/1.1" 304 0
[14/Apr/2025 13:17:11] "GET /static/admin/fonts/Roboto-Light-webfont.woff HTTP/1.1" 304 0
[14/Apr/2025 13:17:11] "GET /static/admin/fonts/Roboto-Regular-webfont.woff HTTP/1.1" 304 0
Not Found: /favicon.ico
[14/Apr/2025 13:17:12] "GET /favicon.ico HTTP/1.1" 404 1982
C:\Users\Msys\Desktop\Axsos_Assignments\python_stack\django\django_orm\single_model_orm\single_model_orm\settings.py changed, reloading.
Watching for file changes with StatReloader
Performing system checks...

System check identified no issues (0 silenced).

You have 17 unapplied migration(s). Your project may not work properly until you apply the migrations for app(s): admin, auth, contenttypes, sessions.
Run 'python manage.py migrate' to apply them.
April 14, 2025 - 13:17:43
Django version 2.2.4, using settings 'single_model_orm.settings'
Starting development server at http://127.0.0.1:8000/
Quit the server with CTRL-BREAK.
C:\Users\Msys\Desktop\Axsos_Assignments\python_stack\django\django_orm\single_model_orm\single_model_orm\settings.py changed, reloading.
Watching for file changes with StatReloader
Performing system checks...

System check identified no issues (0 silenced).

You have 17 unapplied migration(s). Your project may not work properly until you apply the migrations for app(s): admin, auth, contenttypes, sessions.
Run 'python manage.py migrate' to apply them.
April 14, 2025 - 13:17:45
Django version 2.2.4, using settings 'single_model_orm.settings'
Starting development server at http://127.0.0.1:8000/
Quit the server with CTRL-BREAK.
C:\Users\Msys\Desktop\Axsos_Assignments\python_stack\django\django_orm\single_model_orm\single_model_orm\settings.py changed, reloading.
Watching for file changes with StatReloader
Exception in thread django-main-thread:
Traceback (most recent call last):
  File "C:\Users\Msys\AppData\Local\Programs\Python\Python311\Lib\threading.py", line 1038, in _bootstrap_inner
    self.run()
  File "C:\Users\Msys\AppData\Local\Programs\Python\Python311\Lib\threading.py", line 975, in run
    self._target(*self._args, **self._kwargs)
  File "C:\Users\Msys\Desktop\Axsos_Assignments\python_stack\my_environments\py3Env\Lib\site-packages\django\utils\autoreload.py", line 54, in wrapper
    fn(*args, **kwargs)
  File "C:\Users\Msys\Desktop\Axsos_Assignments\python_stack\my_environments\py3Env\Lib\site-packages\django\core\management\commands\runserver.py", line 109, in inner_run
    autoreload.raise_last_exception()
  File "C:\Users\Msys\Desktop\Axsos_Assignments\python_stack\my_environments\py3Env\Lib\site-packages\django\utils\autoreload.py", line 77, in raise_last_exception
    raise _exception[1]
  File "C:\Users\Msys\Desktop\Axsos_Assignments\python_stack\my_environments\py3Env\Lib\site-packages\django\core\management\__init__.py", line 337, in execute
    autoreload.check_errors(django.setup)()
  File "C:\Users\Msys\Desktop\Axsos_Assignments\python_stack\my_environments\py3Env\Lib\site-packages\django\utils\autoreload.py", line 54, in wrapper
    fn(*args, **kwargs)
  File "C:\Users\Msys\Desktop\Axsos_Assignments\python_stack\my_environments\py3Env\Lib\site-packages\django\__init__.py", line 24, in setup
    apps.populate(settings.INSTALLED_APPS)
  File "C:\Users\Msys\Desktop\Axsos_Assignments\python_stack\my_environments\py3Env\Lib\site-packages\django\apps\registry.py", line 91, in populate
    app_config = AppConfig.create(entry)
                 ^^^^^^^^^^^^^^^^^^^^^^^
  File "C:\Users\Msys\Desktop\Axsos_Assignments\python_stack\my_environments\py3Env\Lib\site-packages\django\apps\config.py", line 116, in create
    mod = import_module(mod_path)
          ^^^^^^^^^^^^^^^^^^^^^^^
  File "C:\Users\Msys\AppData\Local\Programs\Python\Python311\Lib\importlib\__init__.py", line 126, in import_module
    return _bootstrap._gcd_import(name[level:], package, level)
           ^^^^^^^^^^^^^^^^^^^^^^^^^^^^^^^^^^^^^^^^^^^^^^^^^^^^
  File "<frozen importlib._bootstrap>", line 1204, in _gcd_import
  File "<frozen importlib._bootstrap>", line 1176, in _find_and_load
  File "<frozen importlib._bootstrap>", line 1126, in _find_and_load_unlocked
  File "<frozen importlib._bootstrap>", line 241, in _call_with_frames_removed
  File "<frozen importlib._bootstrap>", line 1204, in _gcd_import
  File "<frozen importlib._bootstrap>", line 1176, in _find_and_load
  File "<frozen importlib._bootstrap>", line 1140, in _find_and_load_unlocked
ModuleNotFoundError: No module named 'udjango'
C:\Users\Msys\Desktop\Axsos_Assignments\python_stack\django\django_orm\single_model_orm\single_model_orm\settings.py changed, reloading.
Watching for file changes with StatReloader
Exception in thread django-main-thread:
Traceback (most recent call last):
  File "C:\Users\Msys\AppData\Local\Programs\Python\Python311\Lib\threading.py", line 1038, in _bootstrap_inner
    self.run()
  File "C:\Users\Msys\AppData\Local\Programs\Python\Python311\Lib\threading.py", line 975, in run
    self._target(*self._args, **self._kwargs)
  File "C:\Users\Msys\Desktop\Axsos_Assignments\python_stack\my_environments\py3Env\Lib\site-packages\django\utils\autoreload.py", line 54, in wrapper
    fn(*args, **kwargs)
  File "C:\Users\Msys\Desktop\Axsos_Assignments\python_stack\my_environments\py3Env\Lib\site-packages\django\core\management\commands\runserver.py", line 109, in inner_run
    autoreload.raise_last_exception()
  File "C:\Users\Msys\Desktop\Axsos_Assignments\python_stack\my_environments\py3Env\Lib\site-packages\django\utils\autoreload.py", line 77, in raise_last_exception
    raise _exception[1]
  File "C:\Users\Msys\Desktop\Axsos_Assignments\python_stack\my_environments\py3Env\Lib\site-packages\django\core\management\__init__.py", line 337, in execute
    autoreload.check_errors(django.setup)()
  File "C:\Users\Msys\Desktop\Axsos_Assignments\python_stack\my_environments\py3Env\Lib\site-packages\django\utils\autoreload.py", line 54, in wrapper
    fn(*args, **kwargs)
  File "C:\Users\Msys\Desktop\Axsos_Assignments\python_stack\my_environments\py3Env\Lib\site-packages\django\__init__.py", line 24, in setup
    apps.populate(settings.INSTALLED_APPS)
  File "C:\Users\Msys\Desktop\Axsos_Assignments\python_stack\my_environments\py3Env\Lib\site-packages\django\apps\registry.py", line 91, in populate
    app_config = AppConfig.create(entry)
                 ^^^^^^^^^^^^^^^^^^^^^^^
  File "C:\Users\Msys\Desktop\Axsos_Assignments\python_stack\my_environments\py3Env\Lib\site-packages\django\apps\config.py", line 116, in create
    mod = import_module(mod_path)
          ^^^^^^^^^^^^^^^^^^^^^^^
  File "C:\Users\Msys\AppData\Local\Programs\Python\Python311\Lib\importlib\__init__.py", line 126, in import_module
    return _bootstrap._gcd_import(name[level:], package, level)
           ^^^^^^^^^^^^^^^^^^^^^^^^^^^^^^^^^^^^^^^^^^^^^^^^^^^^
  File "<frozen importlib._bootstrap>", line 1204, in _gcd_import
  File "<frozen importlib._bootstrap>", line 1176, in _find_and_load
  File "<frozen importlib._bootstrap>", line 1126, in _find_and_load_unlocked
  File "<frozen importlib._bootstrap>", line 241, in _call_with_frames_removed
  File "<frozen importlib._bootstrap>", line 1204, in _gcd_import
  File "<frozen importlib._bootstrap>", line 1176, in _find_and_load
  File "<frozen importlib._bootstrap>", line 1140, in _find_and_load_unlocked
ModuleNotFoundError: No module named 'users_appdjango'
C:\Users\Msys\Desktop\Axsos_Assignments\python_stack\django\django_orm\single_model_orm\single_model_orm\settings.py changed, reloading.
Watching for file changes with StatReloader
Performing system checks...

System check identified no issues (0 silenced).

You have 17 unapplied migration(s). Your project may not work properly until you apply the migrations for app(s): admin, auth, contenttypes, sessions.
Run 'python manage.py migrate' to apply them.
April 14, 2025 - 13:17:55
Django version 2.2.4, using settings 'single_model_orm.settings'
Starting development server at http://127.0.0.1:8000/
Quit the server with CTRL-BREAK.
C:\Users\Msys\Desktop\Axsos_Assignments\python_stack\django\django_orm\single_model_orm\single_model_orm\urls.py changed, reloading.
Watching for file changes with StatReloader
Performing system checks...

System check identified no issues (0 silenced).

You have 17 unapplied migration(s). Your project may not work properly until you apply the migrations for app(s): admin, auth, contenttypes, sessions.
Run 'python manage.py migrate' to apply them.
April 14, 2025 - 13:18:03
Django version 2.2.4, using settings 'single_model_orm.settings'
Starting development server at http://127.0.0.1:8000/
Quit the server with CTRL-BREAK.
C:\Users\Msys\Desktop\Axsos_Assignments\python_stack\django\django_orm\single_model_orm\single_model_orm\urls.py changed, reloading.
Watching for file changes with StatReloader
Performing system checks...

Exception in thread django-main-thread:
Traceback (most recent call last):
  File "C:\Users\Msys\AppData\Local\Programs\Python\Python311\Lib\threading.py", line 1038, in _bootstrap_inner
    self.run()
  File "C:\Users\Msys\AppData\Local\Programs\Python\Python311\Lib\threading.py", line 975, in run
    self._target(*self._args, **self._kwargs)
  File "C:\Users\Msys\Desktop\Axsos_Assignments\python_stack\my_environments\py3Env\Lib\site-packages\django\utils\autoreload.py", line 54, in wrapper
    fn(*args, **kwargs)
  File "C:\Users\Msys\Desktop\Axsos_Assignments\python_stack\my_environments\py3Env\Lib\site-packages\django\core\management\commands\runserver.py", line 117, in inner_run
    self.check(display_num_errors=True)
  File "C:\Users\Msys\Desktop\Axsos_Assignments\python_stack\my_environments\py3Env\Lib\site-packages\django\core\management\base.py", line 436, in check
    raise SystemCheckError(msg)
django.core.management.base.SystemCheckError: SystemCheckError: System check identified some issues:

ERRORS:
?: (urls.E004) Your URL pattern functools.partial(<function _path at 0x000001F1AED46700>, Pattern=<class 'django.urls.resolvers.RoutePattern'>) is invalid. Ensure that urlpatterns is a list of path() and/or re_path() instances.

System check identified 1 issue (0 silenced).
C:\Users\Msys\Desktop\Axsos_Assignments\python_stack\django\django_orm\single_model_orm\single_model_orm\urls.py changed, reloading.
Watching for file changes with StatReloader
Performing system checks...

Exception in thread django-main-thread:
Traceback (most recent call last):
  File "C:\Users\Msys\AppData\Local\Programs\Python\Python311\Lib\threading.py", line 1038, in _bootstrap_inner
    self.run()
  File "C:\Users\Msys\AppData\Local\Programs\Python\Python311\Lib\threading.py", line 975, in run
    self._target(*self._args, **self._kwargs)
  File "C:\Users\Msys\Desktop\Axsos_Assignments\python_stack\my_environments\py3Env\Lib\site-packages\django\utils\autoreload.py", line 54, in wrapper
    fn(*args, **kwargs)
  File "C:\Users\Msys\Desktop\Axsos_Assignments\python_stack\my_environments\py3Env\Lib\site-packages\django\core\management\commands\runserver.py", line 117, in inner_run
    self.check(display_num_errors=True)
  File "C:\Users\Msys\Desktop\Axsos_Assignments\python_stack\my_environments\py3Env\Lib\site-packages\django\core\management\base.py", line 387, in check
    all_issues = self._run_checks(
                 ^^^^^^^^^^^^^^^^^
  File "C:\Users\Msys\Desktop\Axsos_Assignments\python_stack\my_environments\py3Env\Lib\site-packages\django\core\management\base.py", line 377, in _run_checks
    return checks.run_checks(**kwargs)
           ^^^^^^^^^^^^^^^^^^^^^^^^^^^
  File "C:\Users\Msys\Desktop\Axsos_Assignments\python_stack\my_environments\py3Env\Lib\site-packages\django\core\checks\registry.py", line 72, in run_checks
    new_errors = check(app_configs=app_configs)
                 ^^^^^^^^^^^^^^^^^^^^^^^^^^^^^^
  File "C:\Users\Msys\Desktop\Axsos_Assignments\python_stack\my_environments\py3Env\Lib\site-packages\django\core\checks\urls.py", line 13, in check_url_config
    return check_resolver(resolver)
           ^^^^^^^^^^^^^^^^^^^^^^^^
  File "C:\Users\Msys\Desktop\Axsos_Assignments\python_stack\my_environments\py3Env\Lib\site-packages\django\core\checks\urls.py", line 23, in check_resolver
    return check_method()
           ^^^^^^^^^^^^^^
  File "C:\Users\Msys\Desktop\Axsos_Assignments\python_stack\my_environments\py3Env\Lib\site-packages\django\urls\resolvers.py", line 398, in check
    for pattern in self.url_patterns:
                   ^^^^^^^^^^^^^^^^^
  File "C:\Users\Msys\Desktop\Axsos_Assignments\python_stack\my_environments\py3Env\Lib\site-packages\django\utils\functional.py", line 80, in __get__
    res = instance.__dict__[self.name] = self.func(instance)
                                         ^^^^^^^^^^^^^^^^^^^
  File "C:\Users\Msys\Desktop\Axsos_Assignments\python_stack\my_environments\py3Env\Lib\site-packages\django\urls\resolvers.py", line 579, in url_patterns
    patterns = getattr(self.urlconf_module, "urlpatterns", self.urlconf_module)
                       ^^^^^^^^^^^^^^^^^^^
  File "C:\Users\Msys\Desktop\Axsos_Assignments\python_stack\my_environments\py3Env\Lib\site-packages\django\utils\functional.py", line 80, in __get__
    res = instance.__dict__[self.name] = self.func(instance)
                                         ^^^^^^^^^^^^^^^^^^^
  File "C:\Users\Msys\Desktop\Axsos_Assignments\python_stack\my_environments\py3Env\Lib\site-packages\django\urls\resolvers.py", line 572, in urlconf_module
    return import_module(self.urlconf_name)
           ^^^^^^^^^^^^^^^^^^^^^^^^^^^^^^^^
  File "C:\Users\Msys\AppData\Local\Programs\Python\Python311\Lib\importlib\__init__.py", line 126, in import_module
    return _bootstrap._gcd_import(name[level:], package, level)
           ^^^^^^^^^^^^^^^^^^^^^^^^^^^^^^^^^^^^^^^^^^^^^^^^^^^^
  File "<frozen importlib._bootstrap>", line 1204, in _gcd_import
  File "<frozen importlib._bootstrap>", line 1176, in _find_and_load
  File "<frozen importlib._bootstrap>", line 1147, in _find_and_load_unlocked
  File "<frozen importlib._bootstrap>", line 690, in _load_unlocked
  File "<frozen importlib._bootstrap_external>", line 940, in exec_module
  File "<frozen importlib._bootstrap>", line 241, in _call_with_frames_removed
  File "C:\Users\Msys\Desktop\Axsos_Assignments\python_stack\django\django_orm\single_model_orm\single_model_orm\urls.py", line 21, in <module>
    path('')
TypeError: _path() missing 1 required positional argument: 'view'
C:\Users\Msys\Desktop\Axsos_Assignments\python_stack\django\django_orm\single_model_orm\single_model_orm\urls.py changed, reloading.
Watching for file changes with StatReloader
Performing system checks...

Exception in thread django-main-thread:
Traceback (most recent call last):
  File "C:\Users\Msys\AppData\Local\Programs\Python\Python311\Lib\threading.py", line 1038, in _bootstrap_inner
    self.run()
  File "C:\Users\Msys\AppData\Local\Programs\Python\Python311\Lib\threading.py", line 975, in run
    self._target(*self._args, **self._kwargs)
  File "C:\Users\Msys\Desktop\Axsos_Assignments\python_stack\my_environments\py3Env\Lib\site-packages\django\utils\autoreload.py", line 54, in wrapper
    fn(*args, **kwargs)
  File "C:\Users\Msys\Desktop\Axsos_Assignments\python_stack\my_environments\py3Env\Lib\site-packages\django\core\management\commands\runserver.py", line 117, in inner_run
    self.check(display_num_errors=True)
  File "C:\Users\Msys\Desktop\Axsos_Assignments\python_stack\my_environments\py3Env\Lib\site-packages\django\core\management\base.py", line 387, in check
    all_issues = self._run_checks(
                 ^^^^^^^^^^^^^^^^^
  File "C:\Users\Msys\Desktop\Axsos_Assignments\python_stack\my_environments\py3Env\Lib\site-packages\django\core\management\base.py", line 377, in _run_checks
    return checks.run_checks(**kwargs)
           ^^^^^^^^^^^^^^^^^^^^^^^^^^^
  File "C:\Users\Msys\Desktop\Axsos_Assignments\python_stack\my_environments\py3Env\Lib\site-packages\django\core\checks\registry.py", line 72, in run_checks
    new_errors = check(app_configs=app_configs)
                 ^^^^^^^^^^^^^^^^^^^^^^^^^^^^^^
  File "C:\Users\Msys\Desktop\Axsos_Assignments\python_stack\my_environments\py3Env\Lib\site-packages\django\core\checks\urls.py", line 13, in check_url_config
    return check_resolver(resolver)
           ^^^^^^^^^^^^^^^^^^^^^^^^
  File "C:\Users\Msys\Desktop\Axsos_Assignments\python_stack\my_environments\py3Env\Lib\site-packages\django\core\checks\urls.py", line 23, in check_resolver
    return check_method()
           ^^^^^^^^^^^^^^
  File "C:\Users\Msys\Desktop\Axsos_Assignments\python_stack\my_environments\py3Env\Lib\site-packages\django\urls\resolvers.py", line 398, in check
    for pattern in self.url_patterns:
                   ^^^^^^^^^^^^^^^^^
  File "C:\Users\Msys\Desktop\Axsos_Assignments\python_stack\my_environments\py3Env\Lib\site-packages\django\utils\functional.py", line 80, in __get__
    res = instance.__dict__[self.name] = self.func(instance)
                                         ^^^^^^^^^^^^^^^^^^^
  File "C:\Users\Msys\Desktop\Axsos_Assignments\python_stack\my_environments\py3Env\Lib\site-packages\django\urls\resolvers.py", line 579, in url_patterns
    patterns = getattr(self.urlconf_module, "urlpatterns", self.urlconf_module)
                       ^^^^^^^^^^^^^^^^^^^
  File "C:\Users\Msys\Desktop\Axsos_Assignments\python_stack\my_environments\py3Env\Lib\site-packages\django\utils\functional.py", line 80, in __get__
    res = instance.__dict__[self.name] = self.func(instance)
                                         ^^^^^^^^^^^^^^^^^^^
  File "C:\Users\Msys\Desktop\Axsos_Assignments\python_stack\my_environments\py3Env\Lib\site-packages\django\urls\resolvers.py", line 572, in urlconf_module
    return import_module(self.urlconf_name)
           ^^^^^^^^^^^^^^^^^^^^^^^^^^^^^^^^
  File "C:\Users\Msys\AppData\Local\Programs\Python\Python311\Lib\importlib\__init__.py", line 126, in import_module
    return _bootstrap._gcd_import(name[level:], package, level)
           ^^^^^^^^^^^^^^^^^^^^^^^^^^^^^^^^^^^^^^^^^^^^^^^^^^^^
  File "<frozen importlib._bootstrap>", line 1204, in _gcd_import
  File "<frozen importlib._bootstrap>", line 1176, in _find_and_load
  File "<frozen importlib._bootstrap>", line 1147, in _find_and_load_unlocked
  File "<frozen importlib._bootstrap>", line 690, in _load_unlocked
  File "<frozen importlib._bootstrap_external>", line 936, in exec_module
  File "<frozen importlib._bootstrap_external>", line 1074, in get_code
  File "<frozen importlib._bootstrap_external>", line 1004, in source_to_code
  File "<frozen importlib._bootstrap>", line 241, in _call_with_frames_removed
  File "C:\Users\Msys\Desktop\Axsos_Assignments\python_stack\django\django_orm\single_model_orm\single_model_orm\urls.py", line 21
    path('', include '')
                     ^^
SyntaxError: invalid syntax
C:\Users\Msys\Desktop\Axsos_Assignments\python_stack\django\django_orm\single_model_orm\single_model_orm\urls.py changed, reloading.
Watching for file changes with StatReloader
Performing system checks...

Exception in thread django-main-thread:
Traceback (most recent call last):
  File "C:\Users\Msys\AppData\Local\Programs\Python\Python311\Lib\threading.py", line 1038, in _bootstrap_inner
    self.run()
  File "C:\Users\Msys\AppData\Local\Programs\Python\Python311\Lib\threading.py", line 975, in run
    self._target(*self._args, **self._kwargs)
  File "C:\Users\Msys\Desktop\Axsos_Assignments\python_stack\my_environments\py3Env\Lib\site-packages\django\utils\autoreload.py", line 54, in wrapper
    fn(*args, **kwargs)
  File "C:\Users\Msys\Desktop\Axsos_Assignments\python_stack\my_environments\py3Env\Lib\site-packages\django\core\management\commands\runserver.py", line 117, in inner_run
    self.check(display_num_errors=True)
  File "C:\Users\Msys\Desktop\Axsos_Assignments\python_stack\my_environments\py3Env\Lib\site-packages\django\core\management\base.py", line 387, in check
    all_issues = self._run_checks(
                 ^^^^^^^^^^^^^^^^^
  File "C:\Users\Msys\Desktop\Axsos_Assignments\python_stack\my_environments\py3Env\Lib\site-packages\django\core\management\base.py", line 377, in _run_checks
    return checks.run_checks(**kwargs)
           ^^^^^^^^^^^^^^^^^^^^^^^^^^^
  File "C:\Users\Msys\Desktop\Axsos_Assignments\python_stack\my_environments\py3Env\Lib\site-packages\django\core\checks\registry.py", line 72, in run_checks
    new_errors = check(app_configs=app_configs)
                 ^^^^^^^^^^^^^^^^^^^^^^^^^^^^^^
  File "C:\Users\Msys\Desktop\Axsos_Assignments\python_stack\my_environments\py3Env\Lib\site-packages\django\core\checks\urls.py", line 13, in check_url_config
    return check_resolver(resolver)
           ^^^^^^^^^^^^^^^^^^^^^^^^
  File "C:\Users\Msys\Desktop\Axsos_Assignments\python_stack\my_environments\py3Env\Lib\site-packages\django\core\checks\urls.py", line 23, in check_resolver
    return check_method()
           ^^^^^^^^^^^^^^
  File "C:\Users\Msys\Desktop\Axsos_Assignments\python_stack\my_environments\py3Env\Lib\site-packages\django\urls\resolvers.py", line 398, in check
    for pattern in self.url_patterns:
                   ^^^^^^^^^^^^^^^^^
  File "C:\Users\Msys\Desktop\Axsos_Assignments\python_stack\my_environments\py3Env\Lib\site-packages\django\utils\functional.py", line 80, in __get__
    res = instance.__dict__[self.name] = self.func(instance)
                                         ^^^^^^^^^^^^^^^^^^^
  File "C:\Users\Msys\Desktop\Axsos_Assignments\python_stack\my_environments\py3Env\Lib\site-packages\django\urls\resolvers.py", line 579, in url_patterns
    patterns = getattr(self.urlconf_module, "urlpatterns", self.urlconf_module)
                       ^^^^^^^^^^^^^^^^^^^
  File "C:\Users\Msys\Desktop\Axsos_Assignments\python_stack\my_environments\py3Env\Lib\site-packages\django\utils\functional.py", line 80, in __get__
    res = instance.__dict__[self.name] = self.func(instance)
                                         ^^^^^^^^^^^^^^^^^^^
  File "C:\Users\Msys\Desktop\Axsos_Assignments\python_stack\my_environments\py3Env\Lib\site-packages\django\urls\resolvers.py", line 572, in urlconf_module
    return import_module(self.urlconf_name)
           ^^^^^^^^^^^^^^^^^^^^^^^^^^^^^^^^
  File "C:\Users\Msys\AppData\Local\Programs\Python\Python311\Lib\importlib\__init__.py", line 126, in import_module
    return _bootstrap._gcd_import(name[level:], package, level)
           ^^^^^^^^^^^^^^^^^^^^^^^^^^^^^^^^^^^^^^^^^^^^^^^^^^^^
  File "<frozen importlib._bootstrap>", line 1204, in _gcd_import
  File "<frozen importlib._bootstrap>", line 1176, in _find_and_load
  File "<frozen importlib._bootstrap>", line 1147, in _find_and_load_unlocked
  File "<frozen importlib._bootstrap>", line 690, in _load_unlocked
  File "<frozen importlib._bootstrap_external>", line 936, in exec_module
  File "<frozen importlib._bootstrap_external>", line 1074, in get_code
  File "<frozen importlib._bootstrap_external>", line 1004, in source_to_code
  File "<frozen importlib._bootstrap>", line 241, in _call_with_frames_removed
  File "C:\Users\Msys\Desktop\Axsos_Assignments\python_stack\django\django_orm\single_model_orm\single_model_orm\urls.py", line 21
    path('', include 'users_app')
                     ^^^^^^^^^^^
SyntaxError: invalid syntax
C:\Users\Msys\Desktop\Axsos_Assignments\python_stack\django\django_orm\single_model_orm\single_model_orm\urls.py changed, reloading.
Watching for file changes with StatReloader
Performing system checks...

Exception in thread django-main-thread:
Traceback (most recent call last):
  File "C:\Users\Msys\AppData\Local\Programs\Python\Python311\Lib\threading.py", line 1038, in _bootstrap_inner
    self.run()
  File "C:\Users\Msys\AppData\Local\Programs\Python\Python311\Lib\threading.py", line 975, in run
    self._target(*self._args, **self._kwargs)
  File "C:\Users\Msys\Desktop\Axsos_Assignments\python_stack\my_environments\py3Env\Lib\site-packages\django\utils\autoreload.py", line 54, in wrapper
    fn(*args, **kwargs)
  File "C:\Users\Msys\Desktop\Axsos_Assignments\python_stack\my_environments\py3Env\Lib\site-packages\django\core\management\commands\runserver.py", line 117, in inner_run
    self.check(display_num_errors=True)
  File "C:\Users\Msys\Desktop\Axsos_Assignments\python_stack\my_environments\py3Env\Lib\site-packages\django\core\management\base.py", line 387, in check
    all_issues = self._run_checks(
                 ^^^^^^^^^^^^^^^^^
  File "C:\Users\Msys\Desktop\Axsos_Assignments\python_stack\my_environments\py3Env\Lib\site-packages\django\core\management\base.py", line 377, in _run_checks
    return checks.run_checks(**kwargs)
           ^^^^^^^^^^^^^^^^^^^^^^^^^^^
  File "C:\Users\Msys\Desktop\Axsos_Assignments\python_stack\my_environments\py3Env\Lib\site-packages\django\core\checks\registry.py", line 72, in run_checks
    new_errors = check(app_configs=app_configs)
                 ^^^^^^^^^^^^^^^^^^^^^^^^^^^^^^
  File "C:\Users\Msys\Desktop\Axsos_Assignments\python_stack\my_environments\py3Env\Lib\site-packages\django\core\checks\urls.py", line 13, in check_url_config
    return check_resolver(resolver)
           ^^^^^^^^^^^^^^^^^^^^^^^^
  File "C:\Users\Msys\Desktop\Axsos_Assignments\python_stack\my_environments\py3Env\Lib\site-packages\django\core\checks\urls.py", line 23, in check_resolver
    return check_method()
           ^^^^^^^^^^^^^^
  File "C:\Users\Msys\Desktop\Axsos_Assignments\python_stack\my_environments\py3Env\Lib\site-packages\django\urls\resolvers.py", line 398, in check
    for pattern in self.url_patterns:
                   ^^^^^^^^^^^^^^^^^
  File "C:\Users\Msys\Desktop\Axsos_Assignments\python_stack\my_environments\py3Env\Lib\site-packages\django\utils\functional.py", line 80, in __get__
    res = instance.__dict__[self.name] = self.func(instance)
                                         ^^^^^^^^^^^^^^^^^^^
  File "C:\Users\Msys\Desktop\Axsos_Assignments\python_stack\my_environments\py3Env\Lib\site-packages\django\urls\resolvers.py", line 579, in url_patterns
    patterns = getattr(self.urlconf_module, "urlpatterns", self.urlconf_module)
                       ^^^^^^^^^^^^^^^^^^^
  File "C:\Users\Msys\Desktop\Axsos_Assignments\python_stack\my_environments\py3Env\Lib\site-packages\django\utils\functional.py", line 80, in __get__
    res = instance.__dict__[self.name] = self.func(instance)
                                         ^^^^^^^^^^^^^^^^^^^
  File "C:\Users\Msys\Desktop\Axsos_Assignments\python_stack\my_environments\py3Env\Lib\site-packages\django\urls\resolvers.py", line 572, in urlconf_module
    return import_module(self.urlconf_name)
           ^^^^^^^^^^^^^^^^^^^^^^^^^^^^^^^^
  File "C:\Users\Msys\AppData\Local\Programs\Python\Python311\Lib\importlib\__init__.py", line 126, in import_module
    return _bootstrap._gcd_import(name[level:], package, level)
           ^^^^^^^^^^^^^^^^^^^^^^^^^^^^^^^^^^^^^^^^^^^^^^^^^^^^
  File "<frozen importlib._bootstrap>", line 1204, in _gcd_import
  File "<frozen importlib._bootstrap>", line 1176, in _find_and_load
  File "<frozen importlib._bootstrap>", line 1147, in _find_and_load_unlocked
  File "<frozen importlib._bootstrap>", line 690, in _load_unlocked
  File "<frozen importlib._bootstrap_external>", line 936, in exec_module
  File "<frozen importlib._bootstrap_external>", line 1074, in get_code
  File "<frozen importlib._bootstrap_external>", line 1004, in source_to_code
  File "<frozen importlib._bootstrap>", line 241, in _call_with_frames_removed
  File "C:\Users\Msys\Desktop\Axsos_Assignments\python_stack\django\django_orm\single_model_orm\single_model_orm\urls.py", line 21
    path('', include 'users_app.urls')
                     ^^^^^^^^^^^^^^^^
SyntaxError: invalid syntax
C:\Users\Msys\Desktop\Axsos_Assignments\python_stack\django\django_orm\single_model_orm\single_model_orm\urls.py changed, reloading.
Watching for file changes with StatReloader
Performing system checks...

Exception in thread django-main-thread:
Traceback (most recent call last):
  File "C:\Users\Msys\AppData\Local\Programs\Python\Python311\Lib\threading.py", line 1038, in _bootstrap_inner
    self.run()
  File "C:\Users\Msys\AppData\Local\Programs\Python\Python311\Lib\threading.py", line 975, in run
    self._target(*self._args, **self._kwargs)
  File "C:\Users\Msys\Desktop\Axsos_Assignments\python_stack\my_environments\py3Env\Lib\site-packages\django\utils\autoreload.py", line 54, in wrapper
    fn(*args, **kwargs)
  File "C:\Users\Msys\Desktop\Axsos_Assignments\python_stack\my_environments\py3Env\Lib\site-packages\django\core\management\commands\runserver.py", line 117, in inner_run
    self.check(display_num_errors=True)
  File "C:\Users\Msys\Desktop\Axsos_Assignments\python_stack\my_environments\py3Env\Lib\site-packages\django\core\management\base.py", line 387, in check
    all_issues = self._run_checks(
                 ^^^^^^^^^^^^^^^^^
  File "C:\Users\Msys\Desktop\Axsos_Assignments\python_stack\my_environments\py3Env\Lib\site-packages\django\core\management\base.py", line 377, in _run_checks
    return checks.run_checks(**kwargs)
           ^^^^^^^^^^^^^^^^^^^^^^^^^^^
  File "C:\Users\Msys\Desktop\Axsos_Assignments\python_stack\my_environments\py3Env\Lib\site-packages\django\core\checks\registry.py", line 72, in run_checks
    new_errors = check(app_configs=app_configs)
                 ^^^^^^^^^^^^^^^^^^^^^^^^^^^^^^
  File "C:\Users\Msys\Desktop\Axsos_Assignments\python_stack\my_environments\py3Env\Lib\site-packages\django\core\checks\urls.py", line 13, in check_url_config
    return check_resolver(resolver)
           ^^^^^^^^^^^^^^^^^^^^^^^^
  File "C:\Users\Msys\Desktop\Axsos_Assignments\python_stack\my_environments\py3Env\Lib\site-packages\django\core\checks\urls.py", line 23, in check_resolver
    return check_method()
           ^^^^^^^^^^^^^^
  File "C:\Users\Msys\Desktop\Axsos_Assignments\python_stack\my_environments\py3Env\Lib\site-packages\django\urls\resolvers.py", line 398, in check
    for pattern in self.url_patterns:
                   ^^^^^^^^^^^^^^^^^
  File "C:\Users\Msys\Desktop\Axsos_Assignments\python_stack\my_environments\py3Env\Lib\site-packages\django\utils\functional.py", line 80, in __get__
    res = instance.__dict__[self.name] = self.func(instance)
                                         ^^^^^^^^^^^^^^^^^^^
  File "C:\Users\Msys\Desktop\Axsos_Assignments\python_stack\my_environments\py3Env\Lib\site-packages\django\urls\resolvers.py", line 579, in url_patterns
    patterns = getattr(self.urlconf_module, "urlpatterns", self.urlconf_module)
                       ^^^^^^^^^^^^^^^^^^^
  File "C:\Users\Msys\Desktop\Axsos_Assignments\python_stack\my_environments\py3Env\Lib\site-packages\django\utils\functional.py", line 80, in __get__
    res = instance.__dict__[self.name] = self.func(instance)
                                         ^^^^^^^^^^^^^^^^^^^
  File "C:\Users\Msys\Desktop\Axsos_Assignments\python_stack\my_environments\py3Env\Lib\site-packages\django\urls\resolvers.py", line 572, in urlconf_module
    return import_module(self.urlconf_name)
           ^^^^^^^^^^^^^^^^^^^^^^^^^^^^^^^^
  File "C:\Users\Msys\AppData\Local\Programs\Python\Python311\Lib\importlib\__init__.py", line 126, in import_module
    return _bootstrap._gcd_import(name[level:], package, level)
           ^^^^^^^^^^^^^^^^^^^^^^^^^^^^^^^^^^^^^^^^^^^^^^^^^^^^
  File "<frozen importlib._bootstrap>", line 1204, in _gcd_import
  File "<frozen importlib._bootstrap>", line 1176, in _find_and_load
  File "<frozen importlib._bootstrap>", line 1147, in _find_and_load_unlocked
  File "<frozen importlib._bootstrap>", line 690, in _load_unlocked
  File "<frozen importlib._bootstrap_external>", line 940, in exec_module
  File "<frozen importlib._bootstrap>", line 241, in _call_with_frames_removed
  File "C:\Users\Msys\Desktop\Axsos_Assignments\python_stack\django\django_orm\single_model_orm\single_model_orm\urls.py", line 21, in <module>
    path('', include ('users_app.urls'))
             ^^^^^^^^^^^^^^^^^^^^^^^^^^
  File "C:\Users\Msys\Desktop\Axsos_Assignments\python_stack\my_environments\py3Env\Lib\site-packages\django\urls\conf.py", line 34, in include
    urlconf_module = import_module(urlconf_module)
                     ^^^^^^^^^^^^^^^^^^^^^^^^^^^^^
  File "C:\Users\Msys\AppData\Local\Programs\Python\Python311\Lib\importlib\__init__.py", line 126, in import_module
    return _bootstrap._gcd_import(name[level:], package, level)
           ^^^^^^^^^^^^^^^^^^^^^^^^^^^^^^^^^^^^^^^^^^^^^^^^^^^^
  File "<frozen importlib._bootstrap>", line 1204, in _gcd_import
  File "<frozen importlib._bootstrap>", line 1176, in _find_and_load
  File "<frozen importlib._bootstrap>", line 1140, in _find_and_load_unlocked
ModuleNotFoundError: No module named 'users_app.urls'

(py3Env) C:\Users\Msys\Desktop\Axsos_Assignments\python_stack\django\django_orm\single_model_orm>python manage.py shell
Python 3.11.4 (tags/v3.11.4:d2340ef, Jun  7 2023, 05:45:37) [MSC v.1934 64 bit (AMD64)] on win32
Type "help", "copyright", "credits" or "license" for more information.
(InteractiveConsole)
>>> from users_app.models import *
>>>
KeyboardInterrupt
>>>
KeyboardInterrupt
>>>
KeyboardInterrupt
>>> exit
Use exit() or Ctrl-Z plus Return to exit
>>> exit()

(py3Env) C:\Users\Msys\Desktop\Axsos_Assignments\python_stack\django\django_orm\single_model_orm>python manage.py makemigratios
Traceback (most recent call last):
  File "C:\Users\Msys\Desktop\Axsos_Assignments\python_stack\django\django_orm\single_model_orm\manage.py", line 21, in <module>
    main()
  File "C:\Users\Msys\Desktop\Axsos_Assignments\python_stack\django\django_orm\single_model_orm\manage.py", line 17, in main
    execute_from_command_line(sys.argv)
  File "C:\Users\Msys\Desktop\Axsos_Assignments\python_stack\my_environments\py3Env\Lib\site-packages\django\core\management\__init__.py", line 381, in execute_from_command_line
    utility.execute()
  File "C:\Users\Msys\Desktop\Axsos_Assignments\python_stack\my_environments\py3Env\Lib\site-packages\django\core\management\__init__.py", line 357, in execute
    django.setup()
  File "C:\Users\Msys\Desktop\Axsos_Assignments\python_stack\my_environments\py3Env\Lib\site-packages\django\__init__.py", line 24, in setup
    apps.populate(settings.INSTALLED_APPS)
  File "C:\Users\Msys\Desktop\Axsos_Assignments\python_stack\my_environments\py3Env\Lib\site-packages\django\apps\registry.py", line 114, in populate
    app_config.import_models()
  File "C:\Users\Msys\Desktop\Axsos_Assignments\python_stack\my_environments\py3Env\Lib\site-packages\django\apps\config.py", line 211, in import_models
    self.models_module = import_module(models_module_name)
                         ^^^^^^^^^^^^^^^^^^^^^^^^^^^^^^^^^
  File "C:\Users\Msys\AppData\Local\Programs\Python\Python311\Lib\importlib\__init__.py", line 126, in import_module
    return _bootstrap._gcd_import(name[level:], package, level)
           ^^^^^^^^^^^^^^^^^^^^^^^^^^^^^^^^^^^^^^^^^^^^^^^^^^^^
  File "<frozen importlib._bootstrap>", line 1204, in _gcd_import
  File "<frozen importlib._bootstrap>", line 1176, in _find_and_load
  File "<frozen importlib._bootstrap>", line 1147, in _find_and_load_unlocked
  File "<frozen importlib._bootstrap>", line 690, in _load_unlocked
  File "<frozen importlib._bootstrap_external>", line 940, in exec_module
  File "<frozen importlib._bootstrap>", line 241, in _call_with_frames_removed
  File "C:\Users\Msys\Desktop\Axsos_Assignments\python_stack\django\django_orm\single_model_orm\users_app\models.py", line 3, in <module>
    class User(models.model):
               ^^^^^^^^^^^^
AttributeError: module 'django.db.models' has no attribute 'model'. Did you mean: 'Model'?

(py3Env) C:\Users\Msys\Desktop\Axsos_Assignments\python_stack\django\django_orm\single_model_orm>python manage.py makemigrations
Traceback (most recent call last):
  File "C:\Users\Msys\Desktop\Axsos_Assignments\python_stack\django\django_orm\single_model_orm\manage.py", line 21, in <module>
    main()
  File "C:\Users\Msys\Desktop\Axsos_Assignments\python_stack\django\django_orm\single_model_orm\manage.py", line 17, in main
    execute_from_command_line(sys.argv)
  File "C:\Users\Msys\Desktop\Axsos_Assignments\python_stack\my_environments\py3Env\Lib\site-packages\django\core\management\__init__.py", line 381, in execute_from_command_line
    utility.execute()
  File "C:\Users\Msys\Desktop\Axsos_Assignments\python_stack\my_environments\py3Env\Lib\site-packages\django\core\management\__init__.py", line 357, in execute
    django.setup()
  File "C:\Users\Msys\Desktop\Axsos_Assignments\python_stack\my_environments\py3Env\Lib\site-packages\django\__init__.py", line 24, in setup
    apps.populate(settings.INSTALLED_APPS)
  File "C:\Users\Msys\Desktop\Axsos_Assignments\python_stack\my_environments\py3Env\Lib\site-packages\django\apps\registry.py", line 114, in populate
    app_config.import_models()
  File "C:\Users\Msys\Desktop\Axsos_Assignments\python_stack\my_environments\py3Env\Lib\site-packages\django\apps\config.py", line 211, in import_models
    self.models_module = import_module(models_module_name)
                         ^^^^^^^^^^^^^^^^^^^^^^^^^^^^^^^^^
  File "C:\Users\Msys\AppData\Local\Programs\Python\Python311\Lib\importlib\__init__.py", line 126, in import_module
    return _bootstrap._gcd_import(name[level:], package, level)
           ^^^^^^^^^^^^^^^^^^^^^^^^^^^^^^^^^^^^^^^^^^^^^^^^^^^^
  File "<frozen importlib._bootstrap>", line 1204, in _gcd_import
  File "<frozen importlib._bootstrap>", line 1176, in _find_and_load
  File "<frozen importlib._bootstrap>", line 1147, in _find_and_load_unlocked
  File "<frozen importlib._bootstrap>", line 690, in _load_unlocked
  File "<frozen importlib._bootstrap_external>", line 940, in exec_module
  File "<frozen importlib._bootstrap>", line 241, in _call_with_frames_removed
  File "C:\Users\Msys\Desktop\Axsos_Assignments\python_stack\django\django_orm\single_model_orm\users_app\models.py", line 3, in <module>
    class User(models.model):
               ^^^^^^^^^^^^
AttributeError: module 'django.db.models' has no attribute 'model'. Did you mean: 'Model'?

(py3Env) C:\Users\Msys\Desktop\Axsos_Assignments\python_stack\django\django_orm\single_model_orm>python manage.py makemigrations
Traceback (most recent call last):
  File "C:\Users\Msys\Desktop\Axsos_Assignments\python_stack\django\django_orm\single_model_orm\manage.py", line 21, in <module>
    main()
  File "C:\Users\Msys\Desktop\Axsos_Assignments\python_stack\django\django_orm\single_model_orm\manage.py", line 17, in main
    execute_from_command_line(sys.argv)
  File "C:\Users\Msys\Desktop\Axsos_Assignments\python_stack\my_environments\py3Env\Lib\site-packages\django\core\management\__init__.py", line 381, in execute_from_command_line
    utility.execute()
  File "C:\Users\Msys\Desktop\Axsos_Assignments\python_stack\my_environments\py3Env\Lib\site-packages\django\core\management\__init__.py", line 375, in execute
    self.fetch_command(subcommand).run_from_argv(self.argv)
  File "C:\Users\Msys\Desktop\Axsos_Assignments\python_stack\my_environments\py3Env\Lib\site-packages\django\core\management\base.py", line 323, in run_from_argv
    self.execute(*args, **cmd_options)
  File "C:\Users\Msys\Desktop\Axsos_Assignments\python_stack\my_environments\py3Env\Lib\site-packages\django\core\management\base.py", line 361, in execute
    self.check()
  File "C:\Users\Msys\Desktop\Axsos_Assignments\python_stack\my_environments\py3Env\Lib\site-packages\django\core\management\base.py", line 387, in check
    all_issues = self._run_checks(
                 ^^^^^^^^^^^^^^^^^
  File "C:\Users\Msys\Desktop\Axsos_Assignments\python_stack\my_environments\py3Env\Lib\site-packages\django\core\management\base.py", line 377, in _run_checks
    return checks.run_checks(**kwargs)
           ^^^^^^^^^^^^^^^^^^^^^^^^^^^
  File "C:\Users\Msys\Desktop\Axsos_Assignments\python_stack\my_environments\py3Env\Lib\site-packages\django\core\checks\registry.py", line 72, in run_checks
    new_errors = check(app_configs=app_configs)
                 ^^^^^^^^^^^^^^^^^^^^^^^^^^^^^^
  File "C:\Users\Msys\Desktop\Axsos_Assignments\python_stack\my_environments\py3Env\Lib\site-packages\django\core\checks\urls.py", line 13, in check_url_config
    return check_resolver(resolver)
           ^^^^^^^^^^^^^^^^^^^^^^^^
  File "C:\Users\Msys\Desktop\Axsos_Assignments\python_stack\my_environments\py3Env\Lib\site-packages\django\core\checks\urls.py", line 23, in check_resolver
    return check_method()
           ^^^^^^^^^^^^^^
  File "C:\Users\Msys\Desktop\Axsos_Assignments\python_stack\my_environments\py3Env\Lib\site-packages\django\urls\resolvers.py", line 398, in check
    for pattern in self.url_patterns:
                   ^^^^^^^^^^^^^^^^^
  File "C:\Users\Msys\Desktop\Axsos_Assignments\python_stack\my_environments\py3Env\Lib\site-packages\django\utils\functional.py", line 80, in __get__
    res = instance.__dict__[self.name] = self.func(instance)
                                         ^^^^^^^^^^^^^^^^^^^
  File "C:\Users\Msys\Desktop\Axsos_Assignments\python_stack\my_environments\py3Env\Lib\site-packages\django\urls\resolvers.py", line 579, in url_patterns
    patterns = getattr(self.urlconf_module, "urlpatterns", self.urlconf_module)
                       ^^^^^^^^^^^^^^^^^^^
  File "C:\Users\Msys\Desktop\Axsos_Assignments\python_stack\my_environments\py3Env\Lib\site-packages\django\utils\functional.py", line 80, in __get__
    res = instance.__dict__[self.name] = self.func(instance)
                                         ^^^^^^^^^^^^^^^^^^^
  File "C:\Users\Msys\Desktop\Axsos_Assignments\python_stack\my_environments\py3Env\Lib\site-packages\django\urls\resolvers.py", line 572, in urlconf_module
    return import_module(self.urlconf_name)
           ^^^^^^^^^^^^^^^^^^^^^^^^^^^^^^^^
  File "C:\Users\Msys\AppData\Local\Programs\Python\Python311\Lib\importlib\__init__.py", line 126, in import_module
    return _bootstrap._gcd_import(name[level:], package, level)
           ^^^^^^^^^^^^^^^^^^^^^^^^^^^^^^^^^^^^^^^^^^^^^^^^^^^^
  File "<frozen importlib._bootstrap>", line 1204, in _gcd_import
  File "<frozen importlib._bootstrap>", line 1176, in _find_and_load
  File "<frozen importlib._bootstrap>", line 1147, in _find_and_load_unlocked
  File "<frozen importlib._bootstrap>", line 690, in _load_unlocked
  File "<frozen importlib._bootstrap_external>", line 940, in exec_module
  File "<frozen importlib._bootstrap>", line 241, in _call_with_frames_removed
  File "C:\Users\Msys\Desktop\Axsos_Assignments\python_stack\django\django_orm\single_model_orm\single_model_orm\urls.py", line 21, in <module>
    path('', include ('users_app.urls'))
             ^^^^^^^^^^^^^^^^^^^^^^^^^^
  File "C:\Users\Msys\Desktop\Axsos_Assignments\python_stack\my_environments\py3Env\Lib\site-packages\django\urls\conf.py", line 34, in include
    urlconf_module = import_module(urlconf_module)
                     ^^^^^^^^^^^^^^^^^^^^^^^^^^^^^
  File "C:\Users\Msys\AppData\Local\Programs\Python\Python311\Lib\importlib\__init__.py", line 126, in import_module
    return _bootstrap._gcd_import(name[level:], package, level)
           ^^^^^^^^^^^^^^^^^^^^^^^^^^^^^^^^^^^^^^^^^^^^^^^^^^^^
  File "<frozen importlib._bootstrap>", line 1204, in _gcd_import
  File "<frozen importlib._bootstrap>", line 1176, in _find_and_load
  File "<frozen importlib._bootstrap>", line 1147, in _find_and_load_unlocked
  File "<frozen importlib._bootstrap>", line 690, in _load_unlocked
  File "<frozen importlib._bootstrap_external>", line 940, in exec_module
  File "<frozen importlib._bootstrap>", line 241, in _call_with_frames_removed
  File "C:\Users\Msys\Desktop\Axsos_Assignments\python_stack\django\django_orm\single_model_orm\users_app\urls.py", line 4, in <module>
    path('', views.index ,name ='index'),
             ^^^^^^^^^^^
AttributeError: module 'users_app.views' has no attribute 'index'

(py3Env) C:\Users\Msys\Desktop\Axsos_Assignments\python_stack\django\django_orm\single_model_orm>python manage.py makemigrations
Traceback (most recent call last):
  File "C:\Users\Msys\Desktop\Axsos_Assignments\python_stack\my_environments\py3Env\Lib\site-packages\django\urls\resolvers.py", line 581, in url_patterns
    iter(patterns)
TypeError: 'module' object is not iterable

During handling of the above exception, another exception occurred:

Traceback (most recent call last):
  File "C:\Users\Msys\Desktop\Axsos_Assignments\python_stack\django\django_orm\single_model_orm\manage.py", line 21, in <module>
    main()
  File "C:\Users\Msys\Desktop\Axsos_Assignments\python_stack\django\django_orm\single_model_orm\manage.py", line 17, in main
    execute_from_command_line(sys.argv)
  File "C:\Users\Msys\Desktop\Axsos_Assignments\python_stack\my_environments\py3Env\Lib\site-packages\django\core\management\__init__.py", line 381, in execute_from_command_line
    utility.execute()
  File "C:\Users\Msys\Desktop\Axsos_Assignments\python_stack\my_environments\py3Env\Lib\site-packages\django\core\management\__init__.py", line 375, in execute
    self.fetch_command(subcommand).run_from_argv(self.argv)
  File "C:\Users\Msys\Desktop\Axsos_Assignments\python_stack\my_environments\py3Env\Lib\site-packages\django\core\management\base.py", line 323, in run_from_argv
    self.execute(*args, **cmd_options)
  File "C:\Users\Msys\Desktop\Axsos_Assignments\python_stack\my_environments\py3Env\Lib\site-packages\django\core\management\base.py", line 361, in execute
    self.check()
  File "C:\Users\Msys\Desktop\Axsos_Assignments\python_stack\my_environments\py3Env\Lib\site-packages\django\core\management\base.py", line 387, in check
    all_issues = self._run_checks(
                 ^^^^^^^^^^^^^^^^^
  File "C:\Users\Msys\Desktop\Axsos_Assignments\python_stack\my_environments\py3Env\Lib\site-packages\django\core\management\base.py", line 377, in _run_checks
    return checks.run_checks(**kwargs)
           ^^^^^^^^^^^^^^^^^^^^^^^^^^^
  File "C:\Users\Msys\Desktop\Axsos_Assignments\python_stack\my_environments\py3Env\Lib\site-packages\django\core\checks\registry.py", line 72, in run_checks
    new_errors = check(app_configs=app_configs)
                 ^^^^^^^^^^^^^^^^^^^^^^^^^^^^^^
  File "C:\Users\Msys\Desktop\Axsos_Assignments\python_stack\my_environments\py3Env\Lib\site-packages\django\core\checks\urls.py", line 13, in check_url_config
    return check_resolver(resolver)
           ^^^^^^^^^^^^^^^^^^^^^^^^
  File "C:\Users\Msys\Desktop\Axsos_Assignments\python_stack\my_environments\py3Env\Lib\site-packages\django\core\checks\urls.py", line 23, in check_resolver
    return check_method()
           ^^^^^^^^^^^^^^
  File "C:\Users\Msys\Desktop\Axsos_Assignments\python_stack\my_environments\py3Env\Lib\site-packages\django\urls\resolvers.py", line 399, in check
    messages.extend(check_resolver(pattern))
                    ^^^^^^^^^^^^^^^^^^^^^^^
  File "C:\Users\Msys\Desktop\Axsos_Assignments\python_stack\my_environments\py3Env\Lib\site-packages\django\core\checks\urls.py", line 23, in check_resolver
    return check_method()
           ^^^^^^^^^^^^^^
  File "C:\Users\Msys\Desktop\Axsos_Assignments\python_stack\my_environments\py3Env\Lib\site-packages\django\urls\resolvers.py", line 398, in check
    for pattern in self.url_patterns:
                   ^^^^^^^^^^^^^^^^^
  File "C:\Users\Msys\Desktop\Axsos_Assignments\python_stack\my_environments\py3Env\Lib\site-packages\django\utils\functional.py", line 80, in __get__
    res = instance.__dict__[self.name] = self.func(instance)
                                         ^^^^^^^^^^^^^^^^^^^
  File "C:\Users\Msys\Desktop\Axsos_Assignments\python_stack\my_environments\py3Env\Lib\site-packages\django\urls\resolvers.py", line 588, in url_patterns
    raise ImproperlyConfigured(msg.format(name=self.urlconf_name))
django.core.exceptions.ImproperlyConfigured: The included URLconf '<module 'users_app.urls' from 'C:\\Users\\Msys\\Desktop\\Axsos_Assignments\\python_stack\\django\\django_orm\\single_model_orm\\users_app\\urls.py'>' does not appear to have any patterns in it. If you see valid patterns in the file then the issue is probably caused by a circular import.

(py3Env) C:\Users\Msys\Desktop\Axsos_Assignments\python_stack\django\django_orm\single_model_orm>python manage.py makemigrations
Migrations for 'users_app':
  users_app\migrations\0001_initial.py
    - Create model User

(py3Env) C:\Users\Msys\Desktop\Axsos_Assignments\python_stack\django\django_orm\single_model_orm>python manage.py migrate
Operations to perform:
  Apply all migrations: admin, auth, contenttypes, sessions, users_app
Running migrations:
  Applying contenttypes.0001_initial... OK
  Applying auth.0001_initial... OK
  Applying admin.0001_initial... OK
  Applying admin.0002_logentry_remove_auto_add... OK
  Applying admin.0003_logentry_add_action_flag_choices... OK
  Applying contenttypes.0002_remove_content_type_name... OK
  Applying auth.0002_alter_permission_name_max_length... OK
  Applying auth.0003_alter_user_email_max_length... OK
  Applying auth.0004_alter_user_username_opts... OK
  Applying auth.0005_alter_user_last_login_null... OK
  Applying auth.0006_require_contenttypes_0002... OK
  Applying auth.0007_alter_validators_add_error_messages... OK
  Applying auth.0008_alter_user_username_max_length... OK
  Applying auth.0009_alter_user_last_name_max_length... OK
  Applying auth.0010_alter_group_name_max_length... OK
  Applying auth.0011_update_proxy_permissions... OK
  Applying sessions.0001_initial... OK
  Applying users_app.0001_initial... OK

(py3Env) C:\Users\Msys\Desktop\Axsos_Assignments\python_stack\django\django_orm\single_model_orm>python manage.py shell
Python 3.11.4 (tags/v3.11.4:d2340ef, Jun  7 2023, 05:45:37) [MSC v.1934 64 bit (AMD64)] on win32
Type "help", "copyright", "credits" or "license" for more information.
(InteractiveConsole)
>>> from users_app.models import *
>>> User.objects.create(first_name='Saher', last_name='Kawas', email_address='s.k@gmail.com', age=16)
<User: User object (1)>
>>> User.objects.create(first_name='Omar', last_name='Husseini', email_address='o.h@gmail.com', age=20)
<User: User object (2)>
>>> User.objects.create(first_name='Saeed', last_name='Khaled', email_address='sgg.k@gmail.com', age=50)
<User: User object (3)>
>>> User.objects.all(
...
KeyboardInterrupt
>>> User.objects.all()
<QuerySet [<User: User object (1)>, <User: User object (2)>, <User: User object (3)>]>
>>> User.objects.all().values()
<QuerySet [{'id': 1, 'first_name': 'Saher', 'last_name': 'Kawas', 'email_address': 's.k@gmail.com', 'age': 16, 'created_at': datetime.datetime(2025, 4, 14, 10, 42, 53, 729185, tzinfo=<UTC>), 'updated_at': datetime.datetime(2025, 4, 14, 10, 42, 53, 729185, tzinfo=<UTC>)}, {'id': 2, 'first_name': 'Omar', 'last_name': 'Husseini', 'email_address': 'o.h@gmail.com', 'age': 20, 'created_at': datetime.datetime(2025, 4, 14, 10, 45, 10, 27563, tzinfo=<UTC>), 'updated_at': datetime.datetime(2025, 4, 14, 10, 45, 10, 27563, tzinfo=<UTC>)}, {'id': 3, 'first_name': 'Saeed', 'last_name': 'Khaled', 'email_address': 'sgg.k@gmail.com', 'age': 50, 'created_at': datetime.datetime(2025, 4, 14, 10, 48, 17, 743622, tzinfo=<UTC>), 'updated_at': datetime.datetime(2025, 4, 14, 10, 48, 17, 743622, tzinfo=<UTC>)}]>
>>> User.objects.first()
<User: User object (1)>
>>> User.objects.first().values()
Traceback (most recent call last):
  File "<console>", line 1, in <module>
AttributeError: 'User' object has no attribute 'values'
>>> User.objects.first().value()
Traceback (most recent call last):
  File "<console>", line 1, in <module>
AttributeError: 'User' object has no attribute 'value'
>>> first_name = Users.objects.first()
Traceback (most recent call last):
  File "<console>", line 1, in <module>
NameError: name 'Users' is not defined
>>> first_name = User.objects.first()
>>> print (first_name)
User object (1)
>>> first_name = User.objects.first()
>>> print (first_name.first_name)
Saher
>>> print (first_name.last_name)
Kawas
>>> last_name = Users.objects.last()
Traceback (most recent call last):
  File "<console>", line 1, in <module>
NameError: name 'Users' is not defined
>>> last_user = User.objects.last()
>>> print (last_user.name.age)
Traceback (most recent call last):
  File "<console>", line 1, in <module>
AttributeError: 'User' object has no attribute 'name'
>>> print (last_user.name)
Traceback (most recent call last):
  File "<console>", line 1, in <module>
AttributeError: 'User' object has no attribute 'name'
>>> print (last_user.first_name.age)
Traceback (most recent call last):
  File "<console>", line 1, in <module>
AttributeError: 'str' object has no attribute 'age'
>>> print (last_user.first_name)
Saeed
>>> print (last_user.id)
3
>>> thirduser= User.objects.get(id=3)
>>> thirduser.last_name="Pancakes"
>>> thirduser.save()
>>> seconduser=User.objects.get(id=2)
>>> seconduser.delete()
(1, {'users_app.User': 1})
>>> User.objects.all().order_by("first_name")
<QuerySet [<User: User object (3)>, <User: User object (1)>]>
>>>
